<?xml version="1.0" encoding="UTF-8"?>
<testsuites tests="6" failures="6" time="0.152">
  <testsuite name="Root Suite" timestamp="2024-11-13T01:47:41" tests="6" file="cypress\e2e\tests\NetshoesCpf.cy.js" time="0.152" failures="6">
    <testcase name="An uncaught error was detected outside of a test" time="0.000" classname="An uncaught error was detected outside of a test">
      <failure message="The following error originated from your test code, not from Cypress.

  &gt; Test argument &quot;title&quot; should be a string. Received type &quot;object&quot;

When Cypress detects uncaught errors originating from your test code it will automatically fail the current test.

Cypress could not associate this error to any specific test.

We dynamically generated a new test to display this failure." type="TypeError"><![CDATA[TypeError: The following error originated from your test code, not from Cypress.

  > Test argument "title" should be a string. Received type "object"

When Cypress detects uncaught errors originating from your test code it will automatically fail the current test.

Cypress could not associate this error to any specific test.

We dynamically generated a new test to display this failure.
    at createInvalidArgumentTypeError (http://localhost:55808/__cypress/runner/cypress_runner.js:103081:13)
    at new Test (http://localhost:55808/__cypress/runner/cypress_runner.js:109870:11)
    at context.it.context.specify (http://localhost:55808/__cypress/runner/cypress_runner.js:103281:18)
    at createRunnable (http://localhost:55808/__cypress/runner/cypress_runner.js:162465:31)
    at <unknown> (http://localhost:55808/__cypress/runner/cypress_runner.js:162533:14)
    at Object.create (http://localhost:55808/__cypress/runner/cypress_runner.js:103460:19)
    at context.describe.context.context (http://localhost:55808/__cypress/runner/cypress_runner.js:103236:27)
    at createRunnable (http://localhost:55808/__cypress/runner/cypress_runner.js:162465:31)
    at <unknown> (http://localhost:55808/__cypress/runner/cypress_runner.js:162533:14)
    at <unknown> (http://localhost:55808/__cypress/runner/cypress_runner.js:165590:23)
    at tryCatcher (http://localhost:55808/__cypress/runner/cypress_runner.js:11318:23)
    at Object.gotValue (http://localhost:55808/__cypress/runner/cypress_runner.js:10460:18)
    at Object.gotAccum (http://localhost:55808/__cypress/runner/cypress_runner.js:10449:25)
    at Object.tryCatcher (http://localhost:55808/__cypress/runner/cypress_runner.js:11318:23)
    at Promise._settlePromiseFromHandler (http://localhost:55808/__cypress/runner/cypress_runner.js:9253:31)
    at Promise._settlePromise (http://localhost:55808/__cypress/runner/cypress_runner.js:9310:18)
    at Promise._settlePromise0 (http://localhost:55808/__cypress/runner/cypress_runner.js:9355:10)
    at Promise._settlePromises (http://localhost:55808/__cypress/runner/cypress_runner.js:9435:18)
    at _drainQueueStep (http://localhost:55808/__cypress/runner/cypress_runner.js:6025:12)
    at _drainQueue (http://localhost:55808/__cypress/runner/cypress_runner.js:6018:9)
    at ../../node_modules/bluebird/js/release/async.js.Async._drainQueues (http://localhost:55808/__cypress/runner/cypress_runner.js:6034:5)
    at Async.drainQueues (http://localhost:55808/__cypress/runner/cypress_runner.js:5904:14)]]></failure>
    </testcase>
    <testcase name="An uncaught error was detected outside of a test" time="0.000" classname="An uncaught error was detected outside of a test">
      <failure message="The following error originated from your test code, not from Cypress.

  &gt; Test argument &quot;title&quot; should be a string. Received type &quot;object&quot;

When Cypress detects uncaught errors originating from your test code it will automatically fail the current test.

Cypress could not associate this error to any specific test.

We dynamically generated a new test to display this failure." type="TypeError"><![CDATA[TypeError: The following error originated from your test code, not from Cypress.

  > Test argument "title" should be a string. Received type "object"

When Cypress detects uncaught errors originating from your test code it will automatically fail the current test.

Cypress could not associate this error to any specific test.

We dynamically generated a new test to display this failure.
    at createInvalidArgumentTypeError (http://localhost:55858/__cypress/runner/cypress_runner.js:103081:13)
    at new Test (http://localhost:55858/__cypress/runner/cypress_runner.js:109870:11)
    at context.it.context.specify (http://localhost:55858/__cypress/runner/cypress_runner.js:103281:18)
    at createRunnable (http://localhost:55858/__cypress/runner/cypress_runner.js:162465:31)
    at <unknown> (http://localhost:55858/__cypress/runner/cypress_runner.js:162533:14)
    at Object.create (http://localhost:55858/__cypress/runner/cypress_runner.js:103460:19)
    at context.describe.context.context (http://localhost:55858/__cypress/runner/cypress_runner.js:103236:27)
    at createRunnable (http://localhost:55858/__cypress/runner/cypress_runner.js:162465:31)
    at <unknown> (http://localhost:55858/__cypress/runner/cypress_runner.js:162533:14)
    at <unknown> (http://localhost:55858/__cypress/runner/cypress_runner.js:165590:23)
    at tryCatcher (http://localhost:55858/__cypress/runner/cypress_runner.js:11318:23)
    at Object.gotValue (http://localhost:55858/__cypress/runner/cypress_runner.js:10460:18)
    at Object.gotAccum (http://localhost:55858/__cypress/runner/cypress_runner.js:10449:25)
    at Object.tryCatcher (http://localhost:55858/__cypress/runner/cypress_runner.js:11318:23)
    at Promise._settlePromiseFromHandler (http://localhost:55858/__cypress/runner/cypress_runner.js:9253:31)
    at Promise._settlePromise (http://localhost:55858/__cypress/runner/cypress_runner.js:9310:18)
    at Promise._settlePromise0 (http://localhost:55858/__cypress/runner/cypress_runner.js:9355:10)
    at Promise._settlePromises (http://localhost:55858/__cypress/runner/cypress_runner.js:9435:18)
    at _drainQueueStep (http://localhost:55858/__cypress/runner/cypress_runner.js:6025:12)
    at _drainQueue (http://localhost:55858/__cypress/runner/cypress_runner.js:6018:9)
    at ../../node_modules/bluebird/js/release/async.js.Async._drainQueues (http://localhost:55858/__cypress/runner/cypress_runner.js:6034:5)
    at Async.drainQueues (http://localhost:55858/__cypress/runner/cypress_runner.js:5904:14)]]></failure>
    </testcase>
    <testcase name="An uncaught error was detected outside of a test" time="0.000" classname="An uncaught error was detected outside of a test">
      <failure message="The following error originated from your test code, not from Cypress.

  &gt; Test argument &quot;title&quot; should be a string. Received type &quot;object&quot;

When Cypress detects uncaught errors originating from your test code it will automatically fail the current test.

Cypress could not associate this error to any specific test.

We dynamically generated a new test to display this failure." type="TypeError"><![CDATA[TypeError: The following error originated from your test code, not from Cypress.

  > Test argument "title" should be a string. Received type "object"

When Cypress detects uncaught errors originating from your test code it will automatically fail the current test.

Cypress could not associate this error to any specific test.

We dynamically generated a new test to display this failure.
    at createInvalidArgumentTypeError (http://localhost:55808/__cypress/runner/cypress_runner.js:103081:13)
    at new Test (http://localhost:55808/__cypress/runner/cypress_runner.js:109870:11)
    at context.it.context.specify (http://localhost:55808/__cypress/runner/cypress_runner.js:103281:18)
    at createRunnable (http://localhost:55808/__cypress/runner/cypress_runner.js:162465:31)
    at <unknown> (http://localhost:55808/__cypress/runner/cypress_runner.js:162533:14)
    at Object.create (http://localhost:55808/__cypress/runner/cypress_runner.js:103460:19)
    at context.describe.context.context (http://localhost:55808/__cypress/runner/cypress_runner.js:103236:27)
    at createRunnable (http://localhost:55808/__cypress/runner/cypress_runner.js:162465:31)
    at <unknown> (http://localhost:55808/__cypress/runner/cypress_runner.js:162533:14)
    at <unknown> (http://localhost:55808/__cypress/runner/cypress_runner.js:165590:23)
    at tryCatcher (http://localhost:55808/__cypress/runner/cypress_runner.js:11318:23)
    at Object.gotValue (http://localhost:55808/__cypress/runner/cypress_runner.js:10460:18)
    at Object.gotAccum (http://localhost:55808/__cypress/runner/cypress_runner.js:10449:25)
    at Object.tryCatcher (http://localhost:55808/__cypress/runner/cypress_runner.js:11318:23)
    at Promise._settlePromiseFromHandler (http://localhost:55808/__cypress/runner/cypress_runner.js:9253:31)
    at Promise._settlePromise (http://localhost:55808/__cypress/runner/cypress_runner.js:9310:18)
    at Promise._settlePromise0 (http://localhost:55808/__cypress/runner/cypress_runner.js:9355:10)
    at Promise._settlePromises (http://localhost:55808/__cypress/runner/cypress_runner.js:9435:18)
    at _drainQueueStep (http://localhost:55808/__cypress/runner/cypress_runner.js:6025:12)
    at _drainQueue (http://localhost:55808/__cypress/runner/cypress_runner.js:6018:9)
    at ../../node_modules/bluebird/js/release/async.js.Async._drainQueues (http://localhost:55808/__cypress/runner/cypress_runner.js:6034:5)
    at Async.drainQueues (http://localhost:55808/__cypress/runner/cypress_runner.js:5904:14)]]></failure>
    </testcase>
    <testcase name="An uncaught error was detected outside of a test" time="0.000" classname="An uncaught error was detected outside of a test">
      <failure message="The following error originated from your test code, not from Cypress.

  &gt; Test argument &quot;title&quot; should be a string. Received type &quot;object&quot;

When Cypress detects uncaught errors originating from your test code it will automatically fail the current test.

Cypress could not associate this error to any specific test.

We dynamically generated a new test to display this failure." type="TypeError"><![CDATA[TypeError: The following error originated from your test code, not from Cypress.

  > Test argument "title" should be a string. Received type "object"

When Cypress detects uncaught errors originating from your test code it will automatically fail the current test.

Cypress could not associate this error to any specific test.

We dynamically generated a new test to display this failure.
    at createInvalidArgumentTypeError (http://localhost:55858/__cypress/runner/cypress_runner.js:103081:13)
    at new Test (http://localhost:55858/__cypress/runner/cypress_runner.js:109870:11)
    at context.it.context.specify (http://localhost:55858/__cypress/runner/cypress_runner.js:103281:18)
    at createRunnable (http://localhost:55858/__cypress/runner/cypress_runner.js:162465:31)
    at <unknown> (http://localhost:55858/__cypress/runner/cypress_runner.js:162533:14)
    at Object.create (http://localhost:55858/__cypress/runner/cypress_runner.js:103460:19)
    at context.describe.context.context (http://localhost:55858/__cypress/runner/cypress_runner.js:103236:27)
    at createRunnable (http://localhost:55858/__cypress/runner/cypress_runner.js:162465:31)
    at <unknown> (http://localhost:55858/__cypress/runner/cypress_runner.js:162533:14)
    at <unknown> (http://localhost:55858/__cypress/runner/cypress_runner.js:165590:23)
    at tryCatcher (http://localhost:55858/__cypress/runner/cypress_runner.js:11318:23)
    at Object.gotValue (http://localhost:55858/__cypress/runner/cypress_runner.js:10460:18)
    at Object.gotAccum (http://localhost:55858/__cypress/runner/cypress_runner.js:10449:25)
    at Object.tryCatcher (http://localhost:55858/__cypress/runner/cypress_runner.js:11318:23)
    at Promise._settlePromiseFromHandler (http://localhost:55858/__cypress/runner/cypress_runner.js:9253:31)
    at Promise._settlePromise (http://localhost:55858/__cypress/runner/cypress_runner.js:9310:18)
    at Promise._settlePromise0 (http://localhost:55858/__cypress/runner/cypress_runner.js:9355:10)
    at Promise._settlePromises (http://localhost:55858/__cypress/runner/cypress_runner.js:9435:18)
    at _drainQueueStep (http://localhost:55858/__cypress/runner/cypress_runner.js:6025:12)
    at _drainQueue (http://localhost:55858/__cypress/runner/cypress_runner.js:6018:9)
    at ../../node_modules/bluebird/js/release/async.js.Async._drainQueues (http://localhost:55858/__cypress/runner/cypress_runner.js:6034:5)
    at Async.drainQueues (http://localhost:55858/__cypress/runner/cypress_runner.js:5904:14)]]></failure>
    </testcase>
    <testcase name="An uncaught error was detected outside of a test" time="0.000" classname="An uncaught error was detected outside of a test">
      <failure message="The following error originated from your test code, not from Cypress.

  &gt; Test argument &quot;title&quot; should be a string. Received type &quot;object&quot;

When Cypress detects uncaught errors originating from your test code it will automatically fail the current test.

Cypress could not associate this error to any specific test.

We dynamically generated a new test to display this failure." type="TypeError"><![CDATA[TypeError: The following error originated from your test code, not from Cypress.

  > Test argument "title" should be a string. Received type "object"

When Cypress detects uncaught errors originating from your test code it will automatically fail the current test.

Cypress could not associate this error to any specific test.

We dynamically generated a new test to display this failure.
    at createInvalidArgumentTypeError (http://localhost:55858/__cypress/runner/cypress_runner.js:103081:13)
    at new Test (http://localhost:55858/__cypress/runner/cypress_runner.js:109870:11)
    at context.it.context.specify (http://localhost:55858/__cypress/runner/cypress_runner.js:103281:18)
    at createRunnable (http://localhost:55858/__cypress/runner/cypress_runner.js:162465:31)
    at <unknown> (http://localhost:55858/__cypress/runner/cypress_runner.js:162533:14)
    at Object.create (http://localhost:55858/__cypress/runner/cypress_runner.js:103460:19)
    at context.describe.context.context (http://localhost:55858/__cypress/runner/cypress_runner.js:103236:27)
    at createRunnable (http://localhost:55858/__cypress/runner/cypress_runner.js:162465:31)
    at <unknown> (http://localhost:55858/__cypress/runner/cypress_runner.js:162533:14)
    at <unknown> (http://localhost:55858/__cypress/runner/cypress_runner.js:165590:23)
    at tryCatcher (http://localhost:55858/__cypress/runner/cypress_runner.js:11318:23)
    at Object.gotValue (http://localhost:55858/__cypress/runner/cypress_runner.js:10460:18)
    at Object.gotAccum (http://localhost:55858/__cypress/runner/cypress_runner.js:10449:25)
    at Object.tryCatcher (http://localhost:55858/__cypress/runner/cypress_runner.js:11318:23)
    at Promise._settlePromiseFromHandler (http://localhost:55858/__cypress/runner/cypress_runner.js:9253:31)
    at Promise._settlePromise (http://localhost:55858/__cypress/runner/cypress_runner.js:9310:18)
    at Promise._settlePromise0 (http://localhost:55858/__cypress/runner/cypress_runner.js:9355:10)
    at Promise._settlePromises (http://localhost:55858/__cypress/runner/cypress_runner.js:9435:18)
    at _drainQueueStep (http://localhost:55858/__cypress/runner/cypress_runner.js:6025:12)
    at _drainQueue (http://localhost:55858/__cypress/runner/cypress_runner.js:6018:9)
    at ../../node_modules/bluebird/js/release/async.js.Async._drainQueues (http://localhost:55858/__cypress/runner/cypress_runner.js:6034:5)
    at Async.drainQueues (http://localhost:55858/__cypress/runner/cypress_runner.js:5904:14)]]></failure>
    </testcase>
    <testcase name="An uncaught error was detected outside of a test" time="0.000" classname="An uncaught error was detected outside of a test">
      <failure message="The following error originated from your test code, not from Cypress.

  &gt; Test argument &quot;title&quot; should be a string. Received type &quot;object&quot;

When Cypress detects uncaught errors originating from your test code it will automatically fail the current test.

Cypress could not associate this error to any specific test.

We dynamically generated a new test to display this failure." type="TypeError"><![CDATA[TypeError: The following error originated from your test code, not from Cypress.

  > Test argument "title" should be a string. Received type "object"

When Cypress detects uncaught errors originating from your test code it will automatically fail the current test.

Cypress could not associate this error to any specific test.

We dynamically generated a new test to display this failure.
    at createInvalidArgumentTypeError (http://localhost:55808/__cypress/runner/cypress_runner.js:103081:13)
    at new Test (http://localhost:55808/__cypress/runner/cypress_runner.js:109870:11)
    at context.it.context.specify (http://localhost:55808/__cypress/runner/cypress_runner.js:103281:18)
    at createRunnable (http://localhost:55808/__cypress/runner/cypress_runner.js:162465:31)
    at <unknown> (http://localhost:55808/__cypress/runner/cypress_runner.js:162533:14)
    at Object.create (http://localhost:55808/__cypress/runner/cypress_runner.js:103460:19)
    at context.describe.context.context (http://localhost:55808/__cypress/runner/cypress_runner.js:103236:27)
    at createRunnable (http://localhost:55808/__cypress/runner/cypress_runner.js:162465:31)
    at <unknown> (http://localhost:55808/__cypress/runner/cypress_runner.js:162533:14)
    at <unknown> (http://localhost:55808/__cypress/runner/cypress_runner.js:165590:23)
    at tryCatcher (http://localhost:55808/__cypress/runner/cypress_runner.js:11318:23)
    at Object.gotValue (http://localhost:55808/__cypress/runner/cypress_runner.js:10460:18)
    at Object.gotAccum (http://localhost:55808/__cypress/runner/cypress_runner.js:10449:25)
    at Object.tryCatcher (http://localhost:55808/__cypress/runner/cypress_runner.js:11318:23)
    at Promise._settlePromiseFromHandler (http://localhost:55808/__cypress/runner/cypress_runner.js:9253:31)
    at Promise._settlePromise (http://localhost:55808/__cypress/runner/cypress_runner.js:9310:18)
    at Promise._settlePromise0 (http://localhost:55808/__cypress/runner/cypress_runner.js:9355:10)
    at Promise._settlePromises (http://localhost:55808/__cypress/runner/cypress_runner.js:9435:18)
    at _drainQueueStep (http://localhost:55808/__cypress/runner/cypress_runner.js:6025:12)
    at _drainQueue (http://localhost:55808/__cypress/runner/cypress_runner.js:6018:9)
    at ../../node_modules/bluebird/js/release/async.js.Async._drainQueues (http://localhost:55808/__cypress/runner/cypress_runner.js:6034:5)
    at Async.drainQueues (http://localhost:55808/__cypress/runner/cypress_runner.js:5904:14)]]></failure>
    </testcase>
  </testsuite>
</testsuites>